{
 "cells": [
  {
   "cell_type": "markdown",
   "id": "2c6f12e2-21ab-4a79-ba64-42511b528e6a",
   "metadata": {},
   "source": [
    "Q1. What is an Exception in pthon? Write the difference between Exception and Syntax errors."
   ]
  },
  {
   "cell_type": "markdown",
   "id": "dcbcea51-0536-45f3-8f92-c3cc3f5296ff",
   "metadata": {},
   "source": [
    "Answer 1: An exception is an event, which occurs during the execution of a program that disrupts the normal flow of the program's instructions.\n",
    "Errors cannot be handled, while Python exceptions can be handled at the run time. An error can be a syntax (parsing) error, while there can be many types of exceptions that could occur during the execution and are not unconditionally inoperable."
   ]
  },
  {
   "cell_type": "markdown",
   "id": "d32852ac-1932-4819-855a-cbc04b316697",
   "metadata": {},
   "source": [
    "Q2. What happens when an exception is not handled? Explin with an example."
   ]
  },
  {
   "cell_type": "markdown",
   "id": "6dc367a7-3bb8-4590-95d5-46b4095bf19e",
   "metadata": {},
   "source": [
    "Answer 2: If an exception is not handled (with a catch block), the runtime system will abort the program (i.e. crash) and an exception message will print to the console. \n",
    "If the exception is not handled by an except clause, the exception is re-raised after the finally clause has been executed."
   ]
  },
  {
   "cell_type": "code",
   "execution_count": 1,
   "id": "79892a61-0891-4dfb-a642-5fb4e9cda029",
   "metadata": {},
   "outputs": [],
   "source": [
    "def divide(x, y):\n",
    "    try:\n",
    "        result = x / y\n",
    "    except ZeroDivisionError:\n",
    "        print(\"division by zero!\")\n",
    "    else:\n",
    "        print(\"result is\", result)\n",
    "    finally:\n",
    "        print(\"executing finally clause\")"
   ]
  },
  {
   "cell_type": "code",
   "execution_count": 2,
   "id": "e79a00de-d491-4b69-b7dd-1b32214d3183",
   "metadata": {},
   "outputs": [
    {
     "name": "stdout",
     "output_type": "stream",
     "text": [
      "result is 2.0\n",
      "executing finally clause\n"
     ]
    }
   ],
   "source": [
    "divide(2, 1)  #There is no exception so else msg will be printed"
   ]
  },
  {
   "cell_type": "code",
   "execution_count": 3,
   "id": "31ffab39-6689-4c88-bacb-2252a5c0b598",
   "metadata": {},
   "outputs": [
    {
     "name": "stdout",
     "output_type": "stream",
     "text": [
      "division by zero!\n",
      "executing finally clause\n"
     ]
    }
   ],
   "source": [
    "divide(2, 0)  #Here exception is handled and exception msg get executed"
   ]
  },
  {
   "cell_type": "code",
   "execution_count": 4,
   "id": "bcfd3f32-ed18-4f07-9d92-106ba4f1db58",
   "metadata": {},
   "outputs": [
    {
     "name": "stdout",
     "output_type": "stream",
     "text": [
      "executing finally clause\n"
     ]
    },
    {
     "ename": "TypeError",
     "evalue": "unsupported operand type(s) for /: 'str' and 'str'",
     "output_type": "error",
     "traceback": [
      "\u001b[0;31m---------------------------------------------------------------------------\u001b[0m",
      "\u001b[0;31mTypeError\u001b[0m                                 Traceback (most recent call last)",
      "Cell \u001b[0;32mIn[4], line 1\u001b[0m\n\u001b[0;32m----> 1\u001b[0m \u001b[43mdivide\u001b[49m\u001b[43m(\u001b[49m\u001b[38;5;124;43m\"\u001b[39;49m\u001b[38;5;124;43m2\u001b[39;49m\u001b[38;5;124;43m\"\u001b[39;49m\u001b[43m,\u001b[49m\u001b[43m \u001b[49m\u001b[38;5;124;43m\"\u001b[39;49m\u001b[38;5;124;43m1\u001b[39;49m\u001b[38;5;124;43m\"\u001b[39;49m\u001b[43m)\u001b[49m\n",
      "Cell \u001b[0;32mIn[1], line 3\u001b[0m, in \u001b[0;36mdivide\u001b[0;34m(x, y)\u001b[0m\n\u001b[1;32m      1\u001b[0m \u001b[38;5;28;01mdef\u001b[39;00m \u001b[38;5;21mdivide\u001b[39m(x, y):\n\u001b[1;32m      2\u001b[0m     \u001b[38;5;28;01mtry\u001b[39;00m:\n\u001b[0;32m----> 3\u001b[0m         result \u001b[38;5;241m=\u001b[39m \u001b[43mx\u001b[49m\u001b[43m \u001b[49m\u001b[38;5;241;43m/\u001b[39;49m\u001b[43m \u001b[49m\u001b[43my\u001b[49m\n\u001b[1;32m      4\u001b[0m     \u001b[38;5;28;01mexcept\u001b[39;00m \u001b[38;5;167;01mZeroDivisionError\u001b[39;00m:\n\u001b[1;32m      5\u001b[0m         \u001b[38;5;28mprint\u001b[39m(\u001b[38;5;124m\"\u001b[39m\u001b[38;5;124mdivision by zero!\u001b[39m\u001b[38;5;124m\"\u001b[39m)\n",
      "\u001b[0;31mTypeError\u001b[0m: unsupported operand type(s) for /: 'str' and 'str'"
     ]
    }
   ],
   "source": [
    "divide(\"2\", \"1\")  #Here exception is not handled so finally block will get executed"
   ]
  },
  {
   "cell_type": "markdown",
   "id": "930812c6-c7a3-445b-aacf-f5b79289c564",
   "metadata": {},
   "source": [
    "Q3. Which Python statements are used to catch and handle exceptions? Explin with an example."
   ]
  },
  {
   "cell_type": "markdown",
   "id": "08f808f7-f573-4775-8072-26a246c737ca",
   "metadata": {},
   "source": [
    "Answer 3: The try and except block in Python is used to catch and handle exceptions."
   ]
  },
  {
   "cell_type": "code",
   "execution_count": 6,
   "id": "6ce298bc-6193-4ec1-95e8-c52838710044",
   "metadata": {},
   "outputs": [
    {
     "name": "stdout",
     "output_type": "stream",
     "text": [
      "Something went wrong\n"
     ]
    }
   ],
   "source": [
    "#The try block will generate an exception, because x is not defined:\n",
    "try:\n",
    "  print(x)\n",
    "except:\n",
    "  print(\"Something went wrong\")"
   ]
  },
  {
   "cell_type": "markdown",
   "id": "dedb1ea9-2d54-4381-8444-900cc8519e40",
   "metadata": {},
   "source": [
    "Q4. Explain with an exmple: (a)try and else (b) finally (c) raise"
   ]
  },
  {
   "cell_type": "markdown",
   "id": "7f42287c-2fa2-481a-b96a-f1bd5500ce1a",
   "metadata": {},
   "source": [
    "Answer 4: \n",
    "Try and Else: We can use the else keyword to define a block of code to be executed if no errors were raised:"
   ]
  },
  {
   "cell_type": "code",
   "execution_count": 9,
   "id": "a99aae51-9cba-4812-acad-b10831d5829a",
   "metadata": {},
   "outputs": [
    {
     "name": "stdout",
     "output_type": "stream",
     "text": [
      "Hello\n",
      "Nothing went wrong\n"
     ]
    }
   ],
   "source": [
    "#In this example, the try block does not generate any error:\n",
    "\n",
    "try:\n",
    "  print(\"Hello\")\n",
    "except:\n",
    "  print(\"Something went wrong\")\n",
    "else:\n",
    "  print(\"Nothing went wrong\")"
   ]
  },
  {
   "cell_type": "markdown",
   "id": "81466cc1-2a87-4023-b739-d45da7aa8a57",
   "metadata": {},
   "source": [
    "Finally: The finally block, if specified, will be executed regardless if the try block raises an error or not."
   ]
  },
  {
   "cell_type": "code",
   "execution_count": 7,
   "id": "1228f5a3-36cd-4527-b5c1-066cb512f8c5",
   "metadata": {},
   "outputs": [
    {
     "name": "stdout",
     "output_type": "stream",
     "text": [
      "Something went wrong\n",
      "The 'try except' is finished\n"
     ]
    }
   ],
   "source": [
    "try:\n",
    "  print(x)\n",
    "except:\n",
    "  print(\"Something went wrong\")\n",
    "finally:\n",
    "  print(\"The 'try except' is finished\")"
   ]
  },
  {
   "cell_type": "markdown",
   "id": "59863c4d-b4dd-42ca-8cd8-5b50a0ce5dc3",
   "metadata": {},
   "source": [
    "Raise: As a Python developer we can choose to throw an exception if a condition occurs.\n",
    "To throw (or raise) an exception, use the raise keyword."
   ]
  },
  {
   "cell_type": "code",
   "execution_count": 8,
   "id": "a5cd88bf-db7e-467b-87cc-19ce83ef0374",
   "metadata": {},
   "outputs": [
    {
     "ename": "Exception",
     "evalue": "Sorry, no numbers below zero",
     "output_type": "error",
     "traceback": [
      "\u001b[0;31m---------------------------------------------------------------------------\u001b[0m",
      "\u001b[0;31mException\u001b[0m                                 Traceback (most recent call last)",
      "Cell \u001b[0;32mIn[8], line 6\u001b[0m\n\u001b[1;32m      3\u001b[0m x \u001b[38;5;241m=\u001b[39m \u001b[38;5;241m-\u001b[39m\u001b[38;5;241m1\u001b[39m\n\u001b[1;32m      5\u001b[0m \u001b[38;5;28;01mif\u001b[39;00m x \u001b[38;5;241m<\u001b[39m \u001b[38;5;241m0\u001b[39m:\n\u001b[0;32m----> 6\u001b[0m   \u001b[38;5;28;01mraise\u001b[39;00m \u001b[38;5;167;01mException\u001b[39;00m(\u001b[38;5;124m\"\u001b[39m\u001b[38;5;124mSorry, no numbers below zero\u001b[39m\u001b[38;5;124m\"\u001b[39m)\n",
      "\u001b[0;31mException\u001b[0m: Sorry, no numbers below zero"
     ]
    }
   ],
   "source": [
    "#Raise an error and stop the program if x is lower than 0:\n",
    "\n",
    "x = -1\n",
    "\n",
    "if x < 0:\n",
    "  raise Exception(\"Sorry, no numbers below zero\")"
   ]
  },
  {
   "cell_type": "markdown",
   "id": "ad171fb4-80d5-4db1-a0a1-8a704163ace3",
   "metadata": {},
   "source": [
    "Q5. What are Custom Exceptions in python? Why do we need Custom Exceptions? Explain with an example."
   ]
  },
  {
   "cell_type": "markdown",
   "id": "2bdd3f15-4d00-45ad-8378-f72b2e1e260b",
   "metadata": {},
   "source": [
    "Answer 5: In Python, we can define custom exceptions by creating a new class that is derived from the built-in Exception class.\n",
    "Python is known for its readability and user-friendliness; using custom exceptions can help us improve this even more, especially when we are designing our package. If we decide to avoid, at all costs, custom exceptions by using only built-in ones, we risk decreasing Python's readability.\n",
    "\n",
    "Exceptions need to be derived from the Exception class, either directly or indirectly. Although not mandatory, most of the exceptions are named as names that end in “Error” similar to the naming of the standard exceptions in python. For example:"
   ]
  },
  {
   "cell_type": "code",
   "execution_count": 17,
   "id": "77380bf9-a28d-482f-b702-458f45783262",
   "metadata": {},
   "outputs": [
    {
     "name": "stdout",
     "output_type": "stream",
     "text": [
      "A New Exception occurred: 6\n"
     ]
    }
   ],
   "source": [
    "# A python program to create custom exception\n",
    "# class MyError is derived from super class Exception\n",
    "class MyError(Exception):\n",
    " \n",
    "    # Constructor or Initializer\n",
    "    def __init__(self, value):\n",
    "        self.value = value \n",
    "try:\n",
    "    raise(MyError(3*2)) \n",
    "#Value of Exception is stored in error\n",
    "except MyError as error:\n",
    "    print('A New Exception occurred:',error.value)"
   ]
  },
  {
   "cell_type": "markdown",
   "id": "c7b93ffd-cec3-461a-92f0-86e1668bc80a",
   "metadata": {},
   "source": [
    "Q6. Create a custom exception class. Use this class to handle an exception."
   ]
  },
  {
   "cell_type": "code",
   "execution_count": 3,
   "id": "6bc3a595-3a6e-4e1a-91c2-e9da4989a988",
   "metadata": {},
   "outputs": [
    {
     "name": "stdin",
     "output_type": "stream",
     "text": [
      "Enter a number:  13\n"
     ]
    },
    {
     "name": "stdout",
     "output_type": "stream",
     "text": [
      "Exception occurred: Invalid Age\n"
     ]
    }
   ],
   "source": [
    "# define Python custom exceptions\n",
    "class InvalidAgeException(Exception):\n",
    "    \"Raised when the input value is less than 18\"\n",
    "    pass\n",
    "\n",
    "# we need to guess this number\n",
    "number = 18\n",
    "\n",
    "try:\n",
    "    input_num = int(input(\"Enter a number: \"))\n",
    "    if input_num < number:\n",
    "        raise InvalidAgeException\n",
    "    else:\n",
    "        print(\"Eligible to Vote\")\n",
    "        \n",
    "except InvalidAgeException:\n",
    "    print(\"Exception occurred: Invalid Age\")"
   ]
  },
  {
   "cell_type": "markdown",
   "id": "103d591a-74e7-4634-a882-bfc82c5a5d64",
   "metadata": {},
   "source": [
    "In the above example, we have defined the custom exception InvalidAgeException by creating a new class that is derived from the built-in Exception class.\n",
    "Here, when input_num is smaller than 18, this code generates an exception.\n",
    "When an exception occurs, the rest of the code inside the try block is skipped.\n",
    "The except block catches the user-defined InvalidAgeException exception and statements inside the except block are executed."
   ]
  }
 ],
 "metadata": {
  "kernelspec": {
   "display_name": "Python 3 (ipykernel)",
   "language": "python",
   "name": "python3"
  },
  "language_info": {
   "codemirror_mode": {
    "name": "ipython",
    "version": 3
   },
   "file_extension": ".py",
   "mimetype": "text/x-python",
   "name": "python",
   "nbconvert_exporter": "python",
   "pygments_lexer": "ipython3",
   "version": "3.10.8"
  }
 },
 "nbformat": 4,
 "nbformat_minor": 5
}
